<?xml version="1.0"?>

<robot name="abot" xmlns:xacro="http://ros.org/wiki/xacro">

<xacro:include filename="$(find abot_description)/urdf/robot.gazebo.xacro"/>

<link name="base_link"></link>
<joint name="base_link_to_base" type="fixed">
<parent link="base_link"/>
<child link="chassis" />
<origin rpy="0.0 0 0" xyz="0 0 0"/>
</joint>
<link name="chassis">
<visual>
<origin xyz="9.21702e-10 0.00447478 0.0341544" rpy="0 -0 0" />
<geometry>
<mesh filename="package://abot_description/urdf/chassis.stl"/>
</geometry>
<material name="chassis_material">
<color rgba="0.615686 0.811765 0.929412 1.0"/>
</material>
</visual>
<collision>
<origin xyz="9.21702e-10 0.00447478 0.0341544" rpy="0 -0 0" />
<geometry>
<mesh filename="package://abot_description/urdf/chassis.stl"/>
</geometry>
<material name="chassis_material">
<color rgba="0.615686 0.811765 0.929412 1.0"/>
</material>
</collision>
<inertial>
<origin xyz="2.59429e-05 0.0125232 0.0332544" rpy="0 0 0"/>
<mass value="6.99004" />
<inertia ixx="0.0233749" ixy="1.03273e-05"  ixz="3.30741e-08" iyy="0.0358752" iyz="0.000125105" izz="0.0552125" />
</inertial>
</link>

<link name="wheel">
<visual>
<origin xyz="0 0 -0.009" rpy="-1.5708 -1.5708 0" />
<geometry>
<mesh filename="package://abot_description/urdf/wheel.stl"/>
</geometry>
<material name="wheel_material">
<color rgba="0.615686 0.811765 0.929412 1.0"/>
</material>
</visual>
<!-- Shapes for wheel -->
<collision>
<origin xyz="0 0 -0.009" rpy="0 -0 -1.5708" />
<geometry>
<cylinder length="0.018" radius="0.025" />
</geometry>
</collision>
<inertial>
<origin xyz="0 2.01808e-18 -0.009" rpy="0 0 0"/>
<mass value="1.26704" />
<inertia ixx="0.000232186" ixy="0"  ixz="0" iyy="0.000395951" iyz="0" izz="0.000232186" />
</inertial>
</link>

<joint name="RW" type="continuous">
<origin xyz="0.0846 -0.0295252 0.0241544" rpy="1.5708 -0 1.5708" />
<parent link="chassis" />
<child link="wheel" />
<axis xyz="0 0 -1"/>
<limit effort="1" velocity="20" lower="0" upper="6.28319"/>
<joint_properties friction="0.0"/>
</joint>

<!-- Transmission is important to link the joints and the controller -->
<transmission name="RM_trans">
    <type>transmission_interface/SimpleTransmission</type>
    <joint name="RW">
        <hardwareInterface>hardware_interface/VelocityJointInterface</hardwareInterface>  
    </joint>
    <actuator name="RM_motor">
        <hardwareInterface>VelocityJointInterface</hardwareInterface>
        <mechanicalReduction>1</mechanicalReduction>
    </actuator>
</transmission> 

<link name="wheel_2">
<visual>
<origin xyz="0 0 -0.009" rpy="1.5708 1.5708 0" />
<geometry>
<mesh filename="package://abot_description/urdf/wheel.stl"/>
</geometry>
<material name="wheel_material">
<color rgba="0.615686 0.811765 0.929412 1.0"/>
</material>
</visual>
<!-- Shapes for wheel -->
<collision>
<origin xyz="0 0 -0.009" rpy="3.14159 -0 1.5708" />
<geometry>
<cylinder length="0.018" radius="0.025" />
</geometry>
</collision>
<inertial>
<origin xyz="0 -2.01808e-18 -0.009" rpy="0 0 0"/>
<mass value="1.26704" />
<inertia ixx="0.000232186" ixy="0"  ixz="0" iyy="0.000395951" iyz="0" izz="0.000232186" />
</inertial>
</link>

<joint name="LW" type="continuous">
<origin xyz="-0.0846 -0.0295252 0.0241544" rpy="-1.5708 -0 1.5708" />
<parent link="chassis" />
<child link="wheel_2" />
<axis xyz="0 0 1"/>
<limit effort="1" velocity="20" lower="0" upper="6.28319"/>
<joint_properties friction="0.0"/>
</joint>

<!-- Transmission is important to link the joints and the controller -->
<transmission name="LM_trans">
    <type>transmission_interface/SimpleTransmission</type>
    <joint name="LW">
        <hardwareInterface>hardware_interface/VelocityJointInterface</hardwareInterface>  
    </joint>
    <actuator name="LM_motor">
        <hardwareInterface>VelocityJointInterface</hardwareInterface>
        <mechanicalReduction>1</mechanicalReduction>
    </actuator>
</transmission>


</robot>