<?xml version="1.0"?>

<robot name="abot" xmlns:xacro="http://ros.org/wiki/xacro">

<xacro:include filename="$(find abot_description)/urdf/robot.gazebo.xacro"/>
<xacro:include filename="$(find abot_description)/urdf/_d435.urdf.xacro" />

<link name="base_link"></link>

<joint name="base_link_to_base" type="fixed">
<parent link="base_link"/>
<child link="chassis" />
<origin  xyz="0 0 0.005" rpy="0 0 -1.5708"/> 
</joint>

<link name="chassis">
<visual>
<origin xyz="9.21702e-10 0.00447478 0.0341544" rpy="0 -0 0" />
<geometry>
<mesh filename="package://abot_description/meshes/chassis.stl"/>
</geometry>
<material name="chassis_material">
<color rgba="0.615686 0.811765 0.929412 1.0"/>
</material>
</visual>
<collision>
<origin xyz="9.21702e-10 0.00447478 0.0341544" rpy="0 -0 0" />
<geometry>
<mesh filename="package://abot_description/meshes/chassis.stl"/>
</geometry>
<material name="chassis_material">
<color rgba="0.615686 0.811765 0.929412 1.0"/>
</material>
</collision>
<inertial>
<origin xyz="2.60802e-05 0.012071 0.0333924" rpy="0 0 0"/>
<mass value="6.95327" />
<inertia ixx="0.0230788" ixy="1.02453e-05"  ixz="5.81015e-08" iyy="0.0357403" iyz="4.25929e-05" izz="0.0548321" />
</inertial>
</link>

<link name="wheel">
<visual>
<origin xyz="0 0 -0.009" rpy="-1.5708 -1.5708 0" />
<geometry>
<mesh filename="package://abot_description/meshes/wheel.stl"/>
</geometry>
<material name="wheel_material">
<color rgba="0.615686 0.811765 0.929412 1.0"/>
</material>
</visual>
<!-- Shapes for wheel -->
<collision>
<origin xyz="0 0 -0.009" rpy="0 -0 -1.5708" />
<geometry>
<cylinder length="0.018" radius="0.025" />
</geometry>
</collision>
<inertial>
<origin xyz="0 2.01808e-18 -0.009" rpy="-1.5708 0 0"/>
<mass value="1.26704" />
<inertia ixx="0.000232186" ixy="0"  ixz="0" iyy="0.000395951" iyz="0" izz="0.000232186" />
</inertial>
</link>

<joint name="RW" type="continuous">
<origin xyz="0.0846 -0.0295252 0.0241544" rpy="-1.5708 -0 -1.5708" />
<parent link="chassis" />
<child link="wheel" />
<axis xyz="0 0 -1"/>
</joint>

<!-- Transmission is important to link the joints and the controller -->
<transmission name="RM_trans">
    <type>transmission_interface/SimpleTransmission</type>
    <joint name="RW">
        <hardwareInterface>hardware_interface/VelocityJointInterface</hardwareInterface>  
    </joint>
    <actuator name="RM_motor">
        <hardwareInterface>VelocityJointInterface</hardwareInterface>
        <mechanicalReduction>1</mechanicalReduction>
    </actuator>
</transmission> 

<link name="wheel_2">
<visual>
<origin xyz="0 0 -0.009" rpy="1.5708 1.5708 0" />
<geometry>
<mesh filename="package://abot_description/meshes/wheel.stl"/>
</geometry>
<material name="wheel_material">
<color rgba="0.615686 0.811765 0.929412 1.0"/>
</material>
</visual>
<!-- Shapes for wheel -->
<collision>
<origin xyz="0 0 -0.009" rpy="3.14159 -0 1.5708" />
<geometry>
<cylinder length="0.018" radius="0.025" />
</geometry>
</collision>
<inertial>
<origin xyz="0 -2.01808e-18 -0.009" rpy="-1.5708 0 0"/>
<mass value="1.26704" />
<inertia ixx="0.000232186" ixy="0"  ixz="0" iyy="0.000395951" iyz="0" izz="0.000232186" />
</inertial>
</link>

<joint name="LW" type="continuous">
<origin xyz="-0.0846 -0.0295252 0.0241544" rpy="-1.5708 -0 1.5708" />
<parent link="chassis" />
<child link="wheel_2" />
<axis xyz="0 0 1"/>
</joint>
<!-- Transmission is important to link the joints and the controller -->
<transmission name="LM_trans">
    <type>transmission_interface/SimpleTransmission</type>
    <joint name="LW">
        <hardwareInterface>hardware_interface/VelocityJointInterface</hardwareInterface>  
    </joint>
    <actuator name="LM_motor">
        <hardwareInterface>VelocityJointInterface</hardwareInterface>
        <mechanicalReduction>1</mechanicalReduction>
    </actuator>
</transmission>

<link name="roller">
<visual>
<origin xyz="0 0 -0.094554" rpy="-1.5708 -1.5708 0" />
<geometry>
<mesh filename="package://abot_description/meshes/roller.stl"/>
</geometry>
<material name="roller_material">
<color rgba="0.615686 0.811765 0.929412 1.0"/>
</material>
</visual>
<!-- Shapes for roller -->
<collision>
<origin xyz="0 0 -0.094554" rpy="0 -0 -1.5708" />
<geometry>
<box size="0.01 0.01 0.189108" />
</geometry>
</collision>
<inertial>
<origin xyz="0 4.03616e-19 -0.094554" rpy="0 0 -1.5708"/>
<mass value="0.532463" />
<inertia ixx="0.00159015" ixy="0"  ixz="0" iyy="6.65578e-06" iyz="0" izz="0.00159015" />
</inertial>
</link>

<joint name="Rol" type="fixed">
<origin xyz="0.094554 0.0980656 0.00415444" rpy="1.5708 -0 1.5708" />
<parent link="chassis" />
<child link="roller" />
<axis xyz="0 0 1"/>
</joint>

<!--Lidar and imu -->
  <joint name="imu_joint" type="fixed">
    <parent link="chassis"/>
    <child link="imu_link"/>
    <!--<origin xyz="-0.032 0 0.068" rpy="0 0 0"/>-->
    <origin xyz="0 0 0" rpy="0 0 0"/>-->
  </joint>

  <link name="imu_link"/>

  <joint name="scan_joint" type="fixed">
    <parent link="chassis"/>
    <child link="base_scan"/>
    <!--<origin xyz="-0.032 0 0.172" rpy="0 0 0"/>-->
    <origin xyz="0 0 0.096" rpy="0 0 -1.5708"/>
  </joint>

  <link name="base_scan">
    <visual>
      <origin xyz="0 0 0.0" rpy="0 0 0"/>
      <geometry>
        <mesh filename="package://abot_description/meshes/lds.stl" scale="0.001 0.001 0.001"/>
      </geometry>
      <material name="dark"/>
    </visual>

    <collision>
      <origin xyz="0.015 0 -0.0065" rpy="0 0 0"/>
      <geometry>
        <cylinder length="0.0315" radius="0.055"/>
      </geometry>
    </collision>

    <inertial>
      <mass value="0.114" />
      <origin xyz="0 0 0" />
      <inertia ixx="0.001" ixy="0.0" ixz="0.0"
               iyy="0.001" iyz="0.0"
               izz="0.001" />
    </inertial>
  </link>

  <xacro:sensor_d435 name="camera" topics_ns="camera" parent="chassis" publish_pointcloud="true">
    <origin xyz="0 0.08 0.065" rpy="0 -0.139626 1.5708" /> <!-- tilted 8 degree up -->
  </xacro:sensor_d435> 
</robot>
